# Try...catch!

fun main():no_value
{
    try:
    {
        writeln(8)
    }
    catch(exception):
    {
        throw(exception + " happened!")
    }
}
